# backend/app/auth/auth_utils.py

from fastapi import Depends, HTTPException, status
from fastapi.security import OAuth2PasswordBearer
from jose import JWTError, jwt
from sqlalchemy.orm import Session

from app.core.config import settings  # ✅ Correto!
from app.db.database import get_db
from app.models.usuario import Usuario

oauth2_scheme = OAuth2PasswordBearer(tokenUrl="auth/login")


def get_current_user(
    token: str = Depends(oauth2_scheme), db: Session = Depends(get_db)
) -> Usuario:
    credentials_exception = HTTPException(
        status_code=status.HTTP_401_UNAUTHORIZED,
        detail="Não foi possível validar as credenciais",
        headers={"WWW-Authenticate": "Bearer"},
    )
    try:
        payload = jwt.decode(
            token, settings.SECRET_KEY, algorithms=[settings.ALGORITHM]
        )
        user_id: int = int(payload.get("sub"))  # <- Certifique-se que sub é o ID

        if user_id is None:
            raise credentials_exception
    except JWTError:
        raise credentials_exception

    user = db.query(Usuario).filter(Usuario.id == user_id).first()
    if user is None:
        raise credentials_exception
    return user
